{
    "parts": [
        {
            "x": -1,
            "y": 0,
            "z": 0,
            "elements": [
                "psi:psi_decorative@7"
            ]
        },
        {
            "x": 3,
            "y": 0,
            "z": -4,
            "elements": [
                "psi:psi_decorative@7"
            ]
        },
        {
            "x": -2,
            "y": -2,
            "z": -1,
            "elements": [
                "psi:psi_decorative@7"
            ]
        },
        {
            "x": 2,
            "y": -2,
            "z": -5,
            "elements": [
                "psi:psi_decorative@7"
            ]
        },
        {
            "x": 1,
            "y": 0,
            "z": 0,
            "elements": [
                "psi:psi_decorative@7"
            ]
        },
        {
            "x": 1,
            "y": -2,
            "z": -5,
            "elements": [
                "psi:psi_decorative@8"
            ]
        },
        {
            "x": 2,
            "y": 2,
            "z": -3,
            "elements": [
                "psi:psi_decorative@7"
            ]
        },
        {
            "x": 0,
            "y": -2,
            "z": -5,
            "elements": [
                "psi:psi_decorative@8"
            ]
        },
        {
            "x": 1,
            "y": 2,
            "z": -3,
            "elements": [
                "botania:storage@1"
            ]
        },
        {
            "x": -1,
            "y": -2,
            "z": -5,
            "elements": [
                "psi:psi_decorative@8"
            ]
        },
        {
            "x": -2,
            "y": -2,
            "z": -5,
            "elements": [
                "psi:psi_decorative@7"
            ]
        },
        {
            "x": 0,
            "y": 2,
            "z": -3,
            "elements": [
                "botania:elfglass@0"
            ]
        },
        {
            "x": -1,
            "y": 2,
            "z": -3,
            "elements": [
                "botania:storage@1"
            ]
        },
        {
            "x": -2,
            "y": 2,
            "z": -3,
            "elements": [
                "psi:psi_decorative@7"
            ]
        },
        {
            "x": -3,
            "y": 0,
            "z": -4,
            "elements": [
                "psi:psi_decorative@7"
            ]
        },
        {
            "x": 1,
            "y": -1,
            "z": 0,
            "elements": [
                "psi:psi_decorative@7"
            ]
        },
        {
            "x": 0,
            "y": -1,
            "z": 0,
            "nbt": {"id":"minecraft:tileenergyinputhatch","casingColor":"16730368","energy":"0L","hatchSize":"0"},
            "elements": [
                "modularmachinery:blockenergyinputhatch@0"
            ]
        },
        {
            "x": -1,
            "y": 1,
            "z": 0,
            "elements": [
                "psi:psi_decorative@7"
            ]
        },
        {
            "x": 0,
            "y": 1,
            "z": 0,
            "elements": [
                "psi:psi_decorative@7"
            ]
        },
        {
            "x": -1,
            "y": -1,
            "z": 0,
            "elements": [
                "psi:psi_decorative@7"
            ]
        },
        {
            "x": 3,
            "y": -1,
            "z": -4,
            "elements": [
                "psi:psi_decorative@7"
            ]
        },
        {
            "x": 1,
            "y": 1,
            "z": 0,
            "elements": [
                "psi:psi_decorative@7"
            ]
        },
        {
            "x": 3,
            "y": 1,
            "z": -3,
            "elements": [
                "psi:psi_decorative@7"
            ]
        },
        {
            "x": 1,
            "y": 3,
            "z": -2,
            "elements": [
                "psi:psi_decorative@7"
            ]
        },
        {
            "x": 0,
            "y": 3,
            "z": -2,
            "elements": [
                "psi:psi_decorative@7"
            ]
        },
        {
            "x": -3,
            "y": -1,
            "z": -4,
            "elements": [
                "psi:psi_decorative@7"
            ]
        },
        {
            "x": -1,
            "y": 3,
            "z": -2,
            "elements": [
                "psi:psi_decorative@7"
            ]
        },
        {
            "x": -3,
            "y": 1,
            "z": -3,
            "elements": [
                "psi:psi_decorative@7"
            ]
        },
        {
            "x": 1,
            "y": -2,
            "z": 0,
            "elements": [
                "psi:psi_decorative@7"
            ]
        },
        {
            "x": 0,
            "y": -2,
            "z": 0,
            "elements": [
                "psi:psi_decorative@7"
            ]
        },
        {
            "x": -1,
            "y": -2,
            "z": 0,
            "elements": [
                "psi:psi_decorative@7"
            ]
        },
        {
            "x": 3,
            "y": -2,
            "z": -4,
            "elements": [
                "psi:psi_decorative@7"
            ]
        },
        {
            "x": 3,
            "y": 0,
            "z": -3,
            "nbt": {"id":"minecraft:tileiteminputbus","casingColor":"16730368","inventory":{"inSlots":,"outSlots":,"miscSlots":,"inventoryArray":[{"holderEmpty":"1b","holderId":"0"}],"sides":},"busSize":"0"},
            "elements": [
                "modularmachinery:blockinputbus@0"
            ]
        },
        {
            "x": 2,
            "y": -2,
            "z": -4,
            "elements": [
                "psi:psi_decorative@8"
            ]
        },
        {
            "x": 1,
            "y": -2,
            "z": -4,
            "elements": [
                "botania:storage@1"
            ]
        },
        {
            "x": 2,
            "y": 2,
            "z": -2,
            "elements": [
                "psi:psi_decorative@7"
            ]
        },
        {
            "x": 0,
            "y": -2,
            "z": -4,
            "elements": [
                "botania:storage@1"
            ]
        },
        {
            "x": 1,
            "y": 2,
            "z": -2,
            "elements": [
                "botania:storage@1"
            ]
        },
        {
            "x": -1,
            "y": -2,
            "z": -4,
            "elements": [
                "botania:storage@1"
            ]
        },
        {
            "x": 0,
            "y": 2,
            "z": -2,
            "elements": [
                "botania:storage@1"
            ]
        },
        {
            "x": -2,
            "y": -2,
            "z": -4,
            "elements": [
                "psi:psi_decorative@8"
            ]
        },
        {
            "x": -1,
            "y": 2,
            "z": -2,
            "elements": [
                "botania:storage@1"
            ]
        },
        {
            "x": -3,
            "y": -2,
            "z": -4,
            "elements": [
                "psi:psi_decorative@7"
            ]
        },
        {
            "x": -2,
            "y": 2,
            "z": -2,
            "elements": [
                "psi:psi_decorative@7"
            ]
        },
        {
            "x": -3,
            "y": 0,
            "z": -3,
            "nbt": {"id":"minecraft:tileitemoutputbus","casingColor":"16730368","inventory":{"inSlots":,"outSlots":,"miscSlots":,"inventoryArray":[{"holderEmpty":"1b","holderId":"0"}],"sides":},"busSize":"0"},
            "elements": [
                "modularmachinery:blockoutputbus@0"
            ]
        },
        {
            "x": 1,
            "y": 0,
            "z": -7,
            "elements": [
                "minecraft:stone_button@4"
            ]
        },
        {
            "x": 3,
            "y": -1,
            "z": -3,
            "elements": [
                "psi:psi_decorative@7"
            ]
        },
        {
            "x": 3,
            "y": 1,
            "z": -2,
            "elements": [
                "psi:psi_decorative@7"
            ]
        },
        {
            "x": 0,
            "y": -1,
            "z": -3,
            "nbt": {"id":"minecraft:beacon","Lock":"","Primary":"-1","Secondary":"-1","Levels":"1"},
            "elements": [
                "minecraft:beacon@0"
            ]
        },
        {
            "x": -3,
            "y": -1,
            "z": -3,
            "elements": [
                "psi:psi_decorative@7"
            ]
        },
        {
            "x": -3,
            "y": 1,
            "z": -2,
            "elements": [
                "psi:psi_decorative@7"
            ]
        },
        {
            "x": 1,
            "y": 1,
            "z": -6,
            "elements": [
                "psi:psi_decorative@7"
            ]
        },
        {
            "x": 0,
            "y": 1,
            "z": -6,
            "elements": [
                "psi:psi_decorative@7"
            ]
        },
        {
            "x": -1,
            "y": 1,
            "z": -6,
            "elements": [
                "psi:psi_decorative@7"
            ]
        },
        {
            "x": 3,
            "y": -2,
            "z": -3,
            "elements": [
                "psi:psi_decorative@7"
            ]
        },
        {
            "x": 3,
            "y": 0,
            "z": -2,
            "elements": [
                "psi:psi_decorative@7"
            ]
        },
        {
            "x": 2,
            "y": -2,
            "z": -3,
            "elements": [
                "psi:psi_decorative@8"
            ]
        },
        {
            "x": 1,
            "y": -2,
            "z": -3,
            "elements": [
                "botania:storage@1"
            ]
        },
        {
            "x": 0,
            "y": -2,
            "z": -3,
            "elements": [
                "botania:storage@1"
            ]
        },
        {
            "x": 1,
            "y": 2,
            "z": -1,
            "elements": [
                "psi:psi_decorative@7"
            ]
        },
        {
            "x": -1,
            "y": -2,
            "z": -3,
            "elements": [
                "botania:storage@1"
            ]
        },
        {
            "x": 0,
            "y": 2,
            "z": -1,
            "elements": [
                "psi:psi_decorative@7"
            ]
        },
        {
            "x": -2,
            "y": -2,
            "z": -3,
            "elements": [
                "psi:psi_decorative@8"
            ]
        },
        {
            "x": -1,
            "y": 2,
            "z": -1,
            "elements": [
                "psi:psi_decorative@7"
            ]
        },
        {
            "x": -3,
            "y": -2,
            "z": -3,
            "elements": [
                "psi:psi_decorative@7"
            ]
        },
        {
            "x": -3,
            "y": 0,
            "z": -2,
            "elements": [
                "psi:psi_decorative@7"
            ]
        },
        {
            "x": 1,
            "y": 0,
            "z": -6,
            "elements": [
                "psi:psi_decorative@7"
            ]
        },
        {
            "x": 1,
            "y": 2,
            "z": -5,
            "elements": [
                "psi:psi_decorative@7"
            ]
        },
        {
            "x": 0,
            "y": 0,
            "z": -6,
            "elements": [
                "minecraft:iron_door@9"
            ]
        },
        {
            "x": 0,
            "y": 2,
            "z": -5,
            "elements": [
                "psi:psi_decorative@7"
            ]
        },
        {
            "x": -1,
            "y": 0,
            "z": -6,
            "elements": [
                "psi:psi_decorative@7"
            ]
        },
        {
            "x": -1,
            "y": 2,
            "z": -5,
            "elements": [
                "psi:psi_decorative@7"
            ]
        },
        {
            "x": 3,
            "y": -1,
            "z": -2,
            "elements": [
                "psi:psi_decorative@7"
            ]
        },
        {
            "x": 2,
            "y": 1,
            "z": -1,
            "elements": [
                "psi:psi_decorative@7"
            ]
        },
        {
            "x": -2,
            "y": 1,
            "z": -1,
            "elements": [
                "psi:psi_decorative@7"
            ]
        },
        {
            "x": -3,
            "y": -1,
            "z": -2,
            "elements": [
                "psi:psi_decorative@7"
            ]
        },
        {
            "x": 2,
            "y": 1,
            "z": -5,
            "elements": [
                "psi:psi_decorative@7"
            ]
        },
        {
            "x": 1,
            "y": -1,
            "z": -6,
            "elements": [
                "psi:psi_decorative@7"
            ]
        },
        {
            "x": 0,
            "y": -1,
            "z": -6,
            "elements": [
                "minecraft:iron_door@1"
            ]
        },
        {
            "x": -1,
            "y": -1,
            "z": -6,
            "elements": [
                "psi:psi_decorative@7"
            ]
        },
        {
            "x": 1,
            "y": 3,
            "z": -4,
            "elements": [
                "psi:psi_decorative@7"
            ]
        },
        {
            "x": 0,
            "y": 3,
            "z": -4,
            "elements": [
                "psi:psi_decorative@7"
            ]
        },
        {
            "x": -2,
            "y": 1,
            "z": -5,
            "elements": [
                "psi:psi_decorative@7"
            ]
        },
        {
            "x": -1,
            "y": 3,
            "z": -4,
            "elements": [
                "psi:psi_decorative@7"
            ]
        },
        {
            "x": 3,
            "y": -2,
            "z": -2,
            "elements": [
                "psi:psi_decorative@7"
            ]
        },
        {
            "x": 2,
            "y": -2,
            "z": -2,
            "elements": [
                "psi:psi_decorative@8"
            ]
        },
        {
            "x": 2,
            "y": 0,
            "z": -1,
            "elements": [
                "psi:psi_decorative@8"
            ]
        },
        {
            "x": 1,
            "y": -2,
            "z": -2,
            "elements": [
                "botania:storage@1"
            ]
        },
        {
            "x": 0,
            "y": -2,
            "z": -2,
            "elements": [
                "botania:storage@1"
            ]
        },
        {
            "x": -1,
            "y": -2,
            "z": -2,
            "elements": [
                "botania:storage@1"
            ]
        },
        {
            "x": -2,
            "y": -2,
            "z": -2,
            "elements": [
                "psi:psi_decorative@8"
            ]
        },
        {
            "x": -2,
            "y": 0,
            "z": -1,
            "elements": [
                "psi:psi_decorative@8"
            ]
        },
        {
            "x": 2,
            "y": 0,
            "z": -5,
            "elements": [
                "psi:psi_decorative@8"
            ]
        },
        {
            "x": -3,
            "y": -2,
            "z": -2,
            "elements": [
                "psi:psi_decorative@7"
            ]
        },
        {
            "x": 1,
            "y": -2,
            "z": -6,
            "elements": [
                "psi:psi_decorative@7"
            ]
        },
        {
            "x": 2,
            "y": 2,
            "z": -4,
            "elements": [
                "psi:psi_decorative@7"
            ]
        },
        {
            "x": 0,
            "y": -2,
            "z": -6,
            "elements": [
                "psi:psi_decorative@7"
            ]
        },
        {
            "x": 1,
            "y": 2,
            "z": -4,
            "elements": [
                "botania:storage@1"
            ]
        },
        {
            "x": -1,
            "y": -2,
            "z": -6,
            "elements": [
                "psi:psi_decorative@7"
            ]
        },
        {
            "x": 0,
            "y": 2,
            "z": -4,
            "elements": [
                "botania:storage@1"
            ]
        },
        {
            "x": -1,
            "y": 0,
            "z": -5,
            "elements": [
                "minecraft:stone_button@3"
            ]
        },
        {
            "x": -1,
            "y": 2,
            "z": -4,
            "elements": [
                "botania:storage@1"
            ]
        },
        {
            "x": -2,
            "y": 0,
            "z": -5,
            "elements": [
                "psi:psi_decorative@8"
            ]
        },
        {
            "x": -2,
            "y": 2,
            "z": -4,
            "elements": [
                "psi:psi_decorative@7"
            ]
        },
        {
            "x": 2,
            "y": -1,
            "z": -1,
            "elements": [
                "psi:psi_decorative@7"
            ]
        },
        {
            "x": -2,
            "y": -1,
            "z": -1,
            "elements": [
                "psi:psi_decorative@7"
            ]
        },
        {
            "x": 3,
            "y": 1,
            "z": -4,
            "elements": [
                "psi:psi_decorative@7"
            ]
        },
        {
            "x": 2,
            "y": -1,
            "z": -5,
            "elements": [
                "psi:psi_decorative@7"
            ]
        },
        {
            "x": 1,
            "y": 3,
            "z": -3,
            "elements": [
                "psi:psi_decorative@7"
            ]
        },
        {
            "x": -2,
            "y": -1,
            "z": -5,
            "elements": [
                "psi:psi_decorative@7"
            ]
        },
        {
            "x": 0,
            "y": 3,
            "z": -3,
            "elements": [
                "botania:elfglass@0"
            ]
        },
        {
            "x": -1,
            "y": 3,
            "z": -3,
            "elements": [
                "psi:psi_decorative@7"
            ]
        },
        {
            "x": -3,
            "y": 1,
            "z": -4,
            "elements": [
                "psi:psi_decorative@7"
            ]
        },
        {
            "x": 2,
            "y": -2,
            "z": -1,
            "elements": [
                "psi:psi_decorative@7"
            ]
        },
        {
            "x": 1,
            "y": -2,
            "z": -1,
            "elements": [
                "psi:psi_decorative@8"
            ]
        },
        {
            "x": 0,
            "y": -2,
            "z": -1,
            "elements": [
                "psi:psi_decorative@8"
            ]
        },
        {
            "x": -1,
            "y": -2,
            "z": -1,
            "elements": [
                "psi:psi_decorative@8"
            ]
        }
    ]}